Traceback (most recent call last):
  File "/Volumes/zorg/mb312/.virtualenvs/nipraxis-textbook/lib/python3.8/site-packages/jupyter_cache/executors/utils.py", line 51, in single_nb_execution
    executenb(
  File "/Volumes/zorg/mb312/.virtualenvs/nipraxis-textbook/lib/python3.8/site-packages/nbclient/client.py", line 1204, in execute
    return NotebookClient(nb=nb, resources=resources, km=km, **kwargs).execute()
  File "/Volumes/zorg/mb312/.virtualenvs/nipraxis-textbook/lib/python3.8/site-packages/nbclient/util.py", line 84, in wrapped
    return just_run(coro(*args, **kwargs))
  File "/Volumes/zorg/mb312/.virtualenvs/nipraxis-textbook/lib/python3.8/site-packages/nbclient/util.py", line 62, in just_run
    return loop.run_until_complete(coro)
  File "/usr/local/opt/python@3.8/Frameworks/Python.framework/Versions/3.8/lib/python3.8/asyncio/base_events.py", line 616, in run_until_complete
    return future.result()
  File "/Volumes/zorg/mb312/.virtualenvs/nipraxis-textbook/lib/python3.8/site-packages/nbclient/client.py", line 663, in async_execute
    await self.async_execute_cell(
  File "/Volumes/zorg/mb312/.virtualenvs/nipraxis-textbook/lib/python3.8/site-packages/nbclient/client.py", line 965, in async_execute_cell
    await self._check_raise_for_error(cell, cell_index, exec_reply)
  File "/Volumes/zorg/mb312/.virtualenvs/nipraxis-textbook/lib/python3.8/site-packages/nbclient/client.py", line 862, in _check_raise_for_error
    raise CellExecutionError.from_cell_and_msg(cell, exec_reply_content)
nbclient.exceptions.CellExecutionError: An error occurred while executing the following cell:
------------------
np.loadtxt('some_numbers.txt')
------------------

[0;31m---------------------------------------------------------------------------[0m
[0;31mNameError[0m                                 Traceback (most recent call last)
Input [0;32mIn [5][0m, in [0;36m<cell line: 1>[0;34m()[0m
[0;32m----> 1[0m [43mnp[49m[38;5;241m.[39mloadtxt([38;5;124m'[39m[38;5;124msome_numbers.txt[39m[38;5;124m'[39m)

[0;31mNameError[0m: name 'np' is not defined
NameError: name 'np' is not defined

